Workbook
Name GA4_Resumen_Mes: Datos_GA4!$A$6:$A$41
Name GA4_Resumen_Usuarios: Datos_GA4!$B$6:$B$41
Name GA4_Resumen_Sesiones: Datos_GA4!$E$6:$E$41
Name GA4_Resumen_Vistas: Datos_GA4!$F$6:$F$41
Name GA4_Disp_Categoria: Datos_GA4!$B$123:$B$158
Name GA4_Disp_Usuarios: Datos_GA4!$C$123:$C$158
Name Portal_Calidad_Mes: Datos_Portal!$A$19:$A$28
Name Portal_Calidad_Notas: Datos_Portal!$B$19:$B$28
Name Portal_Calidad_Score: Datos_Portal!$C$19:$C$28
Name Portal_Lecturas_Mes: Datos_Portal!$A$43:$A$44
Name Portal_Lecturas: Datos_Portal!$B$43:$B$44
Name Portal_Lectores: Datos_Portal!$C$43:$C$44
Name Portal_Decena: Datos_Portal!$A$32:$A$39
Name Portal_Decena_Notas: Datos_Portal!$B$32:$B$39

Sheet Resumen
A1: Playbook — Métricas del website
A2: Propuesta de dashboard · generado 2026-08-25 · GA4 G-KVE4HF75TF
A4: LO QUE YA SE PUEDE MEDIR HOY (dato propio del portal)
A5: KPI | B5: Acumulado | C5: Último mes | D5: Mes anterior | E5: Δ | F5: Tendencia
A6: Notas publicadas | B6: =SUM(Datos_Portal!B19:B28) | C6: =INDEX(Datos_Portal!B19:B28,COUNT(Datos_Portal!B19:B28)) | D6: =INDEX(Datos_Portal!B19:B28,COUNT(Datos_Portal!B19:B28)-1) | E6: =IFERROR(C6-D6,"") | F6: =IF(N(E6)>0,"▲ sube",IF(N(E6)<0,"▼ baja","= igual"))
A7: Score promedio | B7: =IFERROR(AVERAGE(Datos_Portal!C19:C28),"") | C7: =INDEX(Datos_Portal!C19:C28,COUNT(Datos_Portal!C19:C28)) | D7: =INDEX(Datos_Portal!C19:C28,COUNT(Datos_Portal!C19:C28)-1) | E7: =IFERROR(C7-D7,"") | F7: =IF(N(E7)>0,"▲ sube",IF(N(E7)<0,"▼ baja","= igual"))
A8: Notas ≥70 (portada fuerte) | B8: =SUM(Datos_Portal!D19:D28) | C8: =INDEX(Datos_Portal!D19:D28,COUNT(Datos_Portal!D19:D28)) | D8: =INDEX(Datos_Portal!D19:D28,COUNT(Datos_Portal!D19:D28)-1) | E8: =IFERROR(C8-D8,"") | F8: =IF(N(E8)>0,"▲ sube",IF(N(E8)<0,"▼ baja","= igual"))
A9: Lecturas propias | B9: =SUM(Datos_Portal!B43:B44) | C9: =INDEX(Datos_Portal!B43:B44,COUNT(Datos_Portal!B43:B44)) | D9: =INDEX(Datos_Portal!B43:B44,COUNT(Datos_Portal!B43:B44)-1) | E9: =IFERROR(C9-D9,"") | F9: =IF(N(E9)>0,"▲ sube",IF(N(E9)<0,"▼ baja","= igual"))
A10: Lectores únicos | B10: =SUM(Datos_Portal!C43:C44) | C10: =INDEX(Datos_Portal!C43:C44,COUNT(Datos_Portal!C43:C44)) | D10: =INDEX(Datos_Portal!C43:C44,COUNT(Datos_Portal!C43:C44)-1) | E10: =IFERROR(C10-D10,"") | F10: =IF(N(E10)>0,"▲ sube",IF(N(E10)<0,"▼ baja","= igual"))
A12: RECURRENCIA Y RECIRCULACIÓN — las dos métricas ancla del área
A13: Métrica | B13: Valor | C13: Lectura
A14: Lecturas por lector | B14: =IFERROR(SUM(Datos_Portal!B43:B44)/SUM(Datos_Portal!C43:C44),"") | C14: Proxy de recirculación. 1.00 = nadie lee una segunda nota.
A15: % de lectores recurrentes | B15: =IFERROR(Datos_Portal!B48/Datos_Portal!A48,"") | C15: Lectores con más de una lectura registrada.
A16: Ambas salen de article_reads, no de GA4: son dato de primera parte y no dependen de consentimiento de cookies de terceros.
A18: LO QUE FALTA INSTRUMENTAR
A19: Métrica | B19: Estado | C19: Qué falta
A20: Usuarios, sesiones, vistas | B20: PENDIENTE DE INSTRUMENTACIÓN | C20: Pegar el export de GA4 en Datos_GA4 (ver Instrucciones).
A21: Canales de adquisición | B21: PENDIENTE DE INSTRUMENTACIÓN | C21: Pegar el export de GA4 en Datos_GA4.
A22: Mobile vs desktop | B22: PENDIENTE DE INSTRUMENTACIÓN | C22: Pegar el export de GA4 en Datos_GA4.
A23: Conversión website → newsletter | B23: PENDIENTE DE INSTRUMENTACIÓN | C23: No existe evento de suscripción en GA4 ni tabla de suscriptores en el portal: los suscriptores viven en Substack. Hay que (a) disparar un evento GA4 en el alta y (b) exportar el total de Substack cada mes.
A24: Tiempo de lectura real | B24: PENDIENTE DE INSTRUMENTACIÓN | C24: El portal guarda reading_time ESTIMADO, no medido. El medido sale de GA4.

Sheet Trafico
A1: Tráfico
A2: Todo aquí se alimenta de Datos_GA4. Mientras esa hoja esté vacía las fórmulas devuelven 0 — eso es correcto, no un error: significa que todavía nadie ha pegado el export.
A4: Mes | B4: Usuarios activos | C4: Sesiones | D4: Vistas | E4: Sesiones por usuario | F4: Vistas por sesión
A5: =IFERROR(INDEX(GA4_Resumen_Mes,1),"") | B5: =IFERROR(INDEX(GA4_Resumen_Usuarios,1),0) | C5: =IFERROR(INDEX(GA4_Resumen_Sesiones,1),0) | D5: =IFERROR(INDEX(GA4_Resumen_Vistas,1),0) | E5: =IFERROR(C5/B5,"") | F5: =IFERROR(D5/C5,"")
A6: =IFERROR(INDEX(GA4_Resumen_Mes,2),"") | B6: =IFERROR(INDEX(GA4_Resumen_Usuarios,2),0) | C6: =IFERROR(INDEX(GA4_Resumen_Sesiones,2),0) | D6: =IFERROR(INDEX(GA4_Resumen_Vistas,2),0) | E6: =IFERROR(C6/B6,"") | F6: =IFERROR(D6/C6,"")
A7: =IFERROR(INDEX(GA4_Resumen_Mes,3),"") | B7: =IFERROR(INDEX(GA4_Resumen_Usuarios,3),0) | C7: =IFERROR(INDEX(GA4_Resumen_Sesiones,3),0) | D7: =IFERROR(INDEX(GA4_Resumen_Vistas,3),0) | E7: =IFERROR(C7/B7,"") | F7: =IFERROR(D7/C7,"")
A8: =IFERROR(INDEX(GA4_Resumen_Mes,4),"") | B8: =IFERROR(INDEX(GA4_Resumen_Usuarios,4),0) | C8: =IFERROR(INDEX(GA4_Resumen_Sesiones,4),0) | D8: =IFERROR(INDEX(GA4_Resumen_Vistas,4),0) | E8: =IFERROR(C8/B8,"") | F8: =IFERROR(D8/C8,"")
A9: =IFERROR(INDEX(GA4_Resumen_Mes,5),"") | B9: =IFERROR(INDEX(GA4_Resumen_Usuarios,5),0) | C9: =IFERROR(INDEX(GA4_Resumen_Sesiones,5),0) | D9: =IFERROR(INDEX(GA4_Resumen_Vistas,5),0) | E9: =IFERROR(C9/B9,"") | F9: =IFERROR(D9/C9,"")
A10: =IFERROR(INDEX(GA4_Resumen_Mes,6),"") | B10: =IFERROR(INDEX(GA4_Resumen_Usuarios,6),0) | C10: =IFERROR(INDEX(GA4_Resumen_Sesiones,6),0) | D10: =IFERROR(INDEX(GA4_Resumen_Vistas,6),0) | E10: =IFERROR(C10/B10,"") | F10: =IFERROR(D10/C10,"")
A11: =IFERROR(INDEX(GA4_Resumen_Mes,7),"") | B11: =IFERROR(INDEX(GA4_Resumen_Usuarios,7),0) | C11: =IFERROR(INDEX(GA4_Resumen_Sesiones,7),0) | D11: =IFERROR(INDEX(GA4_Resumen_Vistas,7),0) | E11: =IFERROR(C11/B11,"") | F11: =IFERROR(D11/C11,"")
A12: =IFERROR(INDEX(GA4_Resumen_Mes,8),"") | B12: =IFERROR(INDEX(GA4_Resumen_Usuarios,8),0) | C12: =IFERROR(INDEX(GA4_Resumen_Sesiones,8),0) | D12: =IFERROR(INDEX(GA4_Resumen_Vistas,8),0) | E12: =IFERROR(C12/B12,"") | F12: =IFERROR(D12/C12,"")
A13: =IFERROR(INDEX(GA4_Resumen_Mes,9),"") | B13: =IFERROR(INDEX(GA4_Resumen_Usuarios,9),0) | C13: =IFERROR(INDEX(GA4_Resumen_Sesiones,9),0) | D13: =IFERROR(INDEX(GA4_Resumen_Vistas,9),0) | E13: =IFERROR(C13/B13,"") | F13: =IFERROR(D13/C13,"")
A14: =IFERROR(INDEX(GA4_Resumen_Mes,10),"") | B14: =IFERROR(INDEX(GA4_Resumen_Usuarios,10),0) | C14: =IFERROR(INDEX(GA4_Resumen_Sesiones,10),0) | D14: =IFERROR(INDEX(GA4_Resumen_Vistas,10),0) | E14: =IFERROR(C14/B14,"") | F14: =IFERROR(D14/C14,"")
A15: =IFERROR(INDEX(GA4_Resumen_Mes,11),"") | B15: =IFERROR(INDEX(GA4_Resumen_Usuarios,11),0) | C15: =IFERROR(INDEX(GA4_Resumen_Sesiones,11),0) | D15: =IFERROR(INDEX(GA4_Resumen_Vistas,11),0) | E15: =IFERROR(C15/B15,"") | F15: =IFERROR(D15/C15,"")
A16: =IFERROR(INDEX(GA4_Resumen_Mes,12),"") | B16: =IFERROR(INDEX(GA4_Resumen_Usuarios,12),0) | C16: =IFERROR(INDEX(GA4_Resumen_Sesiones,12),0) | D16: =IFERROR(INDEX(GA4_Resumen_Vistas,12),0) | E16: =IFERROR(C16/B16,"") | F16: =IFERROR(D16/C16,"")
A18: Fila de referencia — cómo se ve una fila con datos:
A19: EJEMPLO | B19: EJEMPLO 12,000 | C19: EJEMPLO 15,000 | D19: EJEMPLO 22,000 | E19: 1.25 | F19: 1.47

Sheet Contenido
A1: Contenido
A2: Volumen, calidad y cadencia editorial. Dato propio: real desde hoy.
A4: Mes | B4: Notas | C4: Score promedio | D4: Notas ≥70 | E4: % ≥70 | F4: Notas por día activo
A5: =Datos_Portal!A19 | B5: =Datos_Portal!B19 | C5: =Datos_Portal!C19 | D5: =Datos_Portal!D19 | E5: =IFERROR(D5/B5,0) | F5: =Datos_Portal!G19
A6: =Datos_Portal!A20 | B6: =Datos_Portal!B20 | C6: =Datos_Portal!C20 | D6: =Datos_Portal!D20 | E6: =IFERROR(D6/B6,0) | F6: =Datos_Portal!G20
A7: =Datos_Portal!A21 | B7: =Datos_Portal!B21 | C7: =Datos_Portal!C21 | D7: =Datos_Portal!D21 | E7: =IFERROR(D7/B7,0) | F7: =Datos_Portal!G21
A8: =Datos_Portal!A22 | B8: =Datos_Portal!B22 | C8: =Datos_Portal!C22 | D8: =Datos_Portal!D22 | E8: =IFERROR(D8/B8,0) | F8: =Datos_Portal!G22
A9: =Datos_Portal!A23 | B9: =Datos_Portal!B23 | C9: =Datos_Portal!C23 | D9: =Datos_Portal!D23 | E9: =IFERROR(D9/B9,0) | F9: =Datos_Portal!G23
A10: =Datos_Portal!A24 | B10: =Datos_Portal!B24 | C10: =Datos_Portal!C24 | D10: =Datos_Portal!D24 | E10: =IFERROR(D10/B10,0) | F10: =Datos_Portal!G24
A11: =Datos_Portal!A25 | B11: =Datos_Portal!B25 | C11: =Datos_Portal!C25 | D11: =Datos_Portal!D25 | E11: =IFERROR(D11/B11,0) | F11: =Datos_Portal!G25
A12: =Datos_Portal!A26 | B12: =Datos_Portal!B26 | C12: =Datos_Portal!C26 | D12: =Datos_Portal!D26 | E12: =IFERROR(D12/B12,0) | F12: =Datos_Portal!G26
A13: =Datos_Portal!A27 | B13: =Datos_Portal!B27 | C13: =Datos_Portal!C27 | D13: =Datos_Portal!D27 | E13: =IFERROR(D13/B13,0) | F13: =Datos_Portal!G27
A14: =Datos_Portal!A28 | B14: =Datos_Portal!B28 | C14: =Datos_Portal!C28 | D14: =Datos_Portal!D28 | E14: =IFERROR(D14/B14,0) | F14: =Datos_Portal!G28

Sheet Audiencia
A1: Audiencia
A2: Lectores propios y recurrencia. Sale de article_reads, no de GA4.
A4: Mes | B4: Lecturas | C4: Lectores únicos | D4: Lecturas por lector
A5: =Datos_Portal!A43 | B5: =Datos_Portal!B43 | C5: =Datos_Portal!C43 | D5: =IFERROR(B5/C5,"")
A6: =Datos_Portal!A44 | B6: =Datos_Portal!B44 | C6: =Datos_Portal!C44 | D6: =IFERROR(B6/C6,"")
A8: MOBILE VS DESKTOP — pendiente de GA4
A9: Dispositivo | B9: Usuarios | C9: % del total
A10: =IFERROR(INDEX(GA4_Disp_Categoria,1),"") | B10: =IFERROR(INDEX(GA4_Disp_Usuarios,1),0) | C10: =IFERROR(B10/SUM($B$10:$B$13),0)
A11: =IFERROR(INDEX(GA4_Disp_Categoria,2),"") | B11: =IFERROR(INDEX(GA4_Disp_Usuarios,2),0) | C11: =IFERROR(B11/SUM($B$10:$B$13),0)
A12: =IFERROR(INDEX(GA4_Disp_Categoria,3),"") | B12: =IFERROR(INDEX(GA4_Disp_Usuarios,3),0) | C12: =IFERROR(B12/SUM($B$10:$B$13),0)
A13: =IFERROR(INDEX(GA4_Disp_Categoria,4),"") | B13: =IFERROR(INDEX(GA4_Disp_Usuarios,4),0) | C13: =IFERROR(B13/SUM($B$10:$B$13),0)

Sheet Newsletter
A1: Newsletter
A2: PENDIENTE DE INSTRUMENTACIÓN. Los suscriptores viven en Substack, no en el portal: la base tiene 11 cuentas registradas y ninguna tabla de suscripción. Esta hoja queda lista para el día que existan las dos fuentes.
A4: Mes | B4: Suscriptores (Substack) | C4: Altas del mes | D4: Sesiones web (GA4) | E4: Conversión web → newsletter
A5: =IFERROR(INDEX(GA4_Resumen_Mes,1),"") | D5: =IFERROR(INDEX(GA4_Resumen_Sesiones,1),0) | E5: =IFERROR(C5/D5,"")
A6: =IFERROR(INDEX(GA4_Resumen_Mes,2),"") | D6: =IFERROR(INDEX(GA4_Resumen_Sesiones,2),0) | E6: =IFERROR(C6/D6,"")
A7: =IFERROR(INDEX(GA4_Resumen_Mes,3),"") | D7: =IFERROR(INDEX(GA4_Resumen_Sesiones,3),0) | E7: =IFERROR(C7/D7,"")
A8: =IFERROR(INDEX(GA4_Resumen_Mes,4),"") | D8: =IFERROR(INDEX(GA4_Resumen_Sesiones,4),0) | E8: =IFERROR(C8/D8,"")
A9: =IFERROR(INDEX(GA4_Resumen_Mes,5),"") | D9: =IFERROR(INDEX(GA4_Resumen_Sesiones,5),0) | E9: =IFERROR(C9/D9,"")
A10: =IFERROR(INDEX(GA4_Resumen_Mes,6),"") | D10: =IFERROR(INDEX(GA4_Resumen_Sesiones,6),0) | E10: =IFERROR(C10/D10,"")
A11: =IFERROR(INDEX(GA4_Resumen_Mes,7),"") | D11: =IFERROR(INDEX(GA4_Resumen_Sesiones,7),0) | E11: =IFERROR(C11/D11,"")
A12: =IFERROR(INDEX(GA4_Resumen_Mes,8),"") | D12: =IFERROR(INDEX(GA4_Resumen_Sesiones,8),0) | E12: =IFERROR(C12/D12,"")
A13: =IFERROR(INDEX(GA4_Resumen_Mes,9),"") | D13: =IFERROR(INDEX(GA4_Resumen_Sesiones,9),0) | E13: =IFERROR(C13/D13,"")
A14: =IFERROR(INDEX(GA4_Resumen_Mes,10),"") | D14: =IFERROR(INDEX(GA4_Resumen_Sesiones,10),0) | E14: =IFERROR(C14/D14,"")
A15: =IFERROR(INDEX(GA4_Resumen_Mes,11),"") | D15: =IFERROR(INDEX(GA4_Resumen_Sesiones,11),0) | E15: =IFERROR(C15/D15,"")
A16: =IFERROR(INDEX(GA4_Resumen_Mes,12),"") | D16: =IFERROR(INDEX(GA4_Resumen_Sesiones,12),0) | E16: =IFERROR(C16/D16,"")
A18: Fila de referencia:
A19: EJEMPLO 2026-08 | B19: EJEMPLO 4,200 | C19: EJEMPLO 180 | D19: EJEMPLO 15,000 | E19: 1.2%

Sheet Datos_GA4
A1: Datos_GA4 — hoja destino. Pegar aquí el export, sin reformatear.
A2: VACÍA A PROPÓSITO. Esta máquina no tiene credenciales de GA4 (las cuatro claves GA4_* existen en .env.local y están en blanco), así que cualquier cifra aquí sería inventada. Los encabezados son los exactos del export de GA4 G-KVE4HF75TF. Ruta de clics por reporte: docs/metricas-website-runbook.md.
A4: RESUMEN MENSUAL — Informes › Adquisición › Visión general (exportar CSV)
A5: Mes | B5: Usuarios activos | C5: Usuarios nuevos | D5: Usuarios recurrentes | E5: Sesiones | F5: Vistas de página | G5: Duración media de sesión (s) | H5: Tasa de interacción
A43: CANALES — Informes › Adquisición › Adquisición de tráfico
A44: Mes | B44: Canal predeterminado | C44: Sesiones | D44: Usuarios activos | E44: Vistas de página | F44: Tasa de interacción
A82: PÁGINAS — Informes › Interacción › Páginas y pantallas
A83: Mes | B83: Ruta de página | C83: Vistas | D83: Usuarios activos | E83: Tiempo medio de interacción (s)
A121: DISPOSITIVOS — Informes › Tecnología › Detalles de tecnología
A122: Mes | B122: Categoría de dispositivo | C122: Usuarios activos | D122: Sesiones | E122: Tasa de interacción
A160: NEWSLETTER — Explorar › Exploración libre, evento de suscripción
A161: Mes | B161: Nombre de evento | C161: Recuento de eventos | D161: Usuarios activos | E161: Sesiones con el evento

Sheet Datos_Portal
A1: Datos_Portal — consultado en vivo desde la base del portal
A2: Generado 2026-08-25. Todo en esta hoja es real. Para refrescar: POSTGRES_URL=… python3 scripts/build-metrics-dashboard.py
A4: PUBLICACIÓN POR PRODUCTO Y MES
A5: Mes | B5: futbol-business-review | C5: industry-shots | D5: infinitas | E5: la-lana | F5: noticias | G5: Total
A6: 2025-11 | B6: 1 | C6: 0 | D6: 0 | E6: 0 | F6: 0 | G6: =SUM(B6:F6)
A7: 2025-12 | B7: 3 | C7: 0 | D7: 0 | E7: 0 | F7: 0 | G7: =SUM(B7:F7)
A8: 2026-01 | B8: 3 | C8: 0 | D8: 0 | E8: 0 | F8: 0 | G8: =SUM(B8:F8)
A9: 2026-02 | B9: 2 | C9: 0 | D9: 0 | E9: 0 | F9: 0 | G9: =SUM(B9:F9)
A10: 2026-03 | B10: 1 | C10: 0 | D10: 0 | E10: 0 | F10: 0 | G10: =SUM(B10:F10)
A11: 2026-04 | B11: 1 | C11: 0 | D11: 2 | E11: 0 | F11: 0 | G11: =SUM(B11:F11)
A12: 2026-05 | B12: 3 | C12: 0 | D12: 1 | E12: 0 | F12: 0 | G12: =SUM(B12:F12)
A13: 2026-06 | B13: 0 | C13: 3 | D13: 1 | E13: 1 | F13: 0 | G13: =SUM(B13:F13)
A14: 2026-07 | B14: 0 | C14: 53 | D14: 3 | E14: 4 | F14: 0 | G14: =SUM(B14:F14)
A15: 2026-08 | B15: 0 | C15: 61 | D15: 11 | E15: 5 | F15: 18 | G15: =SUM(B15:F15)
A17: CALIDAD Y CADENCIA POR MES
A18: Mes | B18: Notas | C18: Score promedio | D18: Notas ≥70 | E18: Lectura prom. (min) | F18: Días con publicación | G18: Notas por día activo
A19: 2025-11 | B19: 1 | C19: 60 | D19: 0 | E19: 3 | F19: 1 | G19: =IFERROR(B19/F19,"")
A20: 2025-12 | B20: 3 | C20: 61.7 | D20: 0 | E20: 3 | F20: 3 | G20: =IFERROR(B20/F20,"")
A21: 2026-01 | B21: 3 | C21: 59.3 | D21: 0 | E21: 3 | F21: 3 | G21: =IFERROR(B21/F21,"")
A22: 2026-02 | B22: 2 | C22: 50 | D22: 0 | E22: 3 | F22: 2 | G22: =IFERROR(B22/F22,"")
A23: 2026-03 | B23: 1 | C23: 63 | D23: 0 | E23: 3 | F23: 1 | G23: =IFERROR(B23/F23,"")
A24: 2026-04 | B24: 3 | C24: 53.7 | D24: 0 | E24: 2.3 | F24: 3 | G24: =IFERROR(B24/F24,"")
A25: 2026-05 | B25: 4 | C25: 70.8 | D25: 2 | E25: 2.8 | F25: 4 | G25: =IFERROR(B25/F25,"")
A26: 2026-06 | B26: 5 | C26: 45.6 | D26: 0 | E26: 1.2 | F26: 5 | G26: =IFERROR(B26/F26,"")
A27: 2026-07 | B27: 60 | C27: 56.6 | D27: 11 | E27: 1.6 | F27: 14 | G27: =IFERROR(B27/F27,"")
A28: 2026-08 | B28: 95 | C28: 64.9 | D28: 33 | E28: 2.3 | F28: 23 | G28: =IFERROR(B28/F28,"")
A30: DISTRIBUCIÓN DE SCORES (boleta 0–99)
A31: Decena | B31: Notas | C31: % del archivo
A32: 20–29 | B32: 3 | C32: =IFERROR(B32/177,0)
A33: 30–39 | B33: 10 | C33: =IFERROR(B33/177,0)
A34: 40–49 | B34: 36 | C34: =IFERROR(B34/177,0)
A35: 50–59 | B35: 31 | C35: =IFERROR(B35/177,0)
A36: 60–69 | B36: 51 | C36: =IFERROR(B36/177,0)
A37: 70–79 | B37: 16 | C37: =IFERROR(B37/177,0)
A38: 80–89 | B38: 20 | C38: =IFERROR(B38/177,0)
A39: 90–99 | B39: 10 | C39: =IFERROR(B39/177,0)
A41: LECTURAS PROPIAS (article_reads — dato de primera parte)
A42: Mes | B42: Lecturas | C42: Lectores únicos | D42: Lecturas por lector
A43: 2026-07 | B43: 1010 | C43: 938 | D43: =IFERROR(B43/C43,"")
A44: 2026-08 | B44: 12024 | C44: 11681 | D44: =IFERROR(B44/C44,"")
...

Sheet Definiciones
A1: Definiciones
A3: Métrica | B3: Definición en una frase | C3: Fuente exacta | D3: Frecuencia | E3: Por qué le importa al CEO | F3: Estado
A4: Usuarios activos | B4: Personas distintas que abrieron al menos una página en el periodo. | C4: GA4 › Adquisición › Visión general | D4: Mensual | E4: Es el tamaño real de la audiencia; sin esto no hay denominador para nada más. | F4: PENDIENTE DE INSTRUMENTACIÓN
A5: Usuarios recurrentes | B5: Usuarios que ya habían visitado antes del periodo. | C5: GA4 › Retención + article_reads del portal | D5: Mensual | E5: Un medio que sólo capta usuarios nuevos alquila audiencia; no la construye. | F5: PARCIAL — el dato propio ya existe
A6: Lecturas por lector | B6: Lecturas registradas ÷ lectores únicos. | C6: Portal › article_reads | D6: Mensual | E6: Recirculación. Si vale 1.00, cada visitante lee una nota y se va: el archivo no trabaja. | F6: REAL
A7: % de lectores recurrentes | B7: Lectores con más de una lectura ÷ lectores totales. | C7: Portal › article_reads | D7: Mensual | E7: Mide si el portal genera hábito o sólo picos de tráfico. | F7: REAL
A8: Conversión web → newsletter | B8: Altas de newsletter ÷ sesiones del periodo. | C8: Substack (altas) + GA4 (sesiones) | D8: Mensual | E8: Convierte tráfico prestado en audiencia propia; es el activo que no depende de un algoritmo. | F8: PENDIENTE DE INSTRUMENTACIÓN
A9: Notas publicadas | B9: Artículos con status published en el periodo. | C9: Portal › articles | D9: Mensual | E9: Velocidad de publicación: la capacidad instalada de la redacción. | F9: REAL
A10: Score promedio (boleta 0–99) | B10: Promedio del score de la boleta editorial. | C10: Portal › articles.score (lib/rank.ts) | D10: Mensual | E10: Calidad de publicación medida por lo que la nota CONTIENE, no por entusiasmo. | F10: REAL
A11: Notas ≥70 | B11: Notas que superan el umbral de portada fuerte. | C11: Portal › articles.score | D11: Mensual | E11: Cuántas piezas de verdad mueven la aguja, no cuántas se publicaron. | F11: REAL
A12: Cobertura de tags | B12: Notas con cada campo de taxonomía poblado. | C12: Portal › articles.tags_* | D12: Mensual | E12: Un archivo mal etiquetado no se puede recircular ni vender por vertical. | F12: REAL
A13: Sesiones / Vistas de página | B13: Visitas y páginas vistas en el periodo. | C13: GA4 › Adquisición e Interacción | D13: Mensual | E13: Base de tráfico y contexto de todo lo demás. | F13: PENDIENTE DE INSTRUMENTACIÓN
A14: Canales de adquisición | B14: De dónde llega el tráfico (orgánico, social, directo, referral). | C14: GA4 › Adquisición de tráfico | D14: Mensual | E14: Dice qué parte de la audiencia es propia y qué parte es alquilada a una plataforma. | F14: PENDIENTE DE INSTRUMENTACIÓN
... A17: Top artículos | B17: Notas más leídas del periodo. | C17: Portal › article_reads (propio) y GA4 › Páginas | D17: Mensual | E17: Muestra qué temas pagan, con dato propio que no depende de consentimiento de cookies. | F17: REAL

Sheet Instrucciones
A1: Instrucciones
A3: Actualizar este archivo cada mes — 4 pasos
A4: 1 | B4: Abrir GA4 y hacer los cinco exports que lista docs/metricas-website-runbook.md. Ese documento trae la ruta de clics exacta, el rango de fechas, y las dimensiones y métricas de cada reporte. Está escrito para alguien que nunca ha abierto GA4.
A5: 2 | B5: Pegar cada export en su bloque de la hoja Datos_GA4, empezando en la primera fila vacía DEBAJO del encabezado. No reordenar ni renombrar columnas: las fórmulas y las gráficas apuntan a rangos con nombre y esperan ese orden.
A6: 3 | B6: Refrescar el dato del portal ejecutando, desde la raíz del repo: POSTGRES_URL=… python3 scripts/build-metrics-dashboard.py Eso regenera el archivo con los números de la base al día.
A7: 4 | B7: Revisar la hoja Resumen. Las gráficas y los KPI se recalculan solos; no hay ningún número escrito a mano dentro de una gráfica.
A9: Reglas de este archivo
A10: · | B10: Ninguna gráfica contiene valores fijos: todas leen rangos de celdas. Cambiar un dato cambia la gráfica sin tocarla.
A11: · | B11: Las filas marcadas EJEMPLO en ámbar son ilustrativas y NO entran en ningún cálculo. Se pueden borrar sin romper nada.
A12: · | B12: Datos_Portal es real y se regenera desde la base. Datos_GA4 nace vacía a propósito: no hay credenciales de GA4 en el repo, y una cifra inventada en un dashboard de dirección es peor que una celda vacía.
A13: · | B13: Lo que hoy no se puede medir aparece como PENDIENTE DE INSTRUMENTACIÓN en Resumen y en Definiciones, en vez de omitirse. Un hueco visible se arregla; uno omitido no.
